Workbook

Sheet Customer Names
A1: Customer ID | B1: name
A2: Id1 | B2: Hawks, Ms. Kelly
A3: Id2 | B3: Lehner, Mr. Matthew D
A4: Id3 | B4: Lu, Mr. Phil
A5: Id4 | B5: Osborne, Ms. Kelsey
A6: Id5 | B6: Kadala, Ms. Kristyn
A7: Id6 | B7: Baker, Mr. Russell B.
A8: Id7 | B8: Macpherson, Mr. Scott
A9: Id8 | B9: Hallman, Mr. Stephen
A10: Id9 | B10: Moran, Mr. Patrick R.
A11: Id10 | B11: Benner, Ms. Brooke N.
A12: Id11 | B12: Fierro Vargas, Ms. Paola Andrea
... A2336: Id2335 | B2336: German, Mr. Aaron K

Sheet Medical Examinations
A1: Customer ID | B1: BMI | C1: HBA1C | D1: Heart Issues | E1: Any Transplants | F1: Cancer history | G1: NumberOfMajorSurgeries | H1: smoker
A2: Id1 | B2: 47.41 | C2: 7.47 | D2: No | E2: No | F2: No | G2: No major surgery | H2: yes
A3: Id2 | B3: 30.36 | C3: 5.77 | D3: No | E3: No | F3: No | G3: No major surgery | H3: yes
A4: Id3 | B4: 34.485 | C4: 11.87 | D4: yes | E4: No | F4: No | G4: 2 | H4: yes
A5: Id4 | B5: 38.095 | C5: 6.05 | D5: No | E5: No | F5: No | G5: No major surgery | H5: yes
A6: Id5 | B6: 35.53 | C6: 5.45 | D6: No | E6: No | F6: No | G6: No major surgery | H6: yes
A7: Id6 | B7: 32.8 | C7: 6.59 | D7: No | E7: No | F7: No | G7: No major surgery | H7: yes
A8: Id7 | B8: 36.4 | C8: 6.07 | D8: No | E8: No | F8: No | G8: No major surgery | H8: yes
A9: Id8 | B9: 36.96 | C9: 7.93 | D9: No | E9: No | F9: No | G9: 3 | H9: yes
A10: Id9 | B10: 41.14 | C10: 9.58 | D10: yes | E10: No | F10: Yes | G10: 1 | H10: yes
A11: Id10 | B11: 38.06 | C11: 10.79 | D11: No | E11: No | F11: No | G11: No major surgery | H11: yes
A12: Id11 | B12: 37.7 | C12: 5.96 | D12: yes | E12: No | F12: No | G12: 2 | H12: yes
A13: Id12 | B13: 42.13 | C13: 11.9 | D13: No | E13: No | F13: No | G13: No major surgery | H13: yes
A14: Id13 | B14: 40.92 | C14: 8.41 | D14: No | E14: No | F14: No | G14: No major surgery | H14: yes
A15: Id14 | B15: 40.565 | C15: 7.02 | D15: No | E15: No | F15: No | G15: No major surgery | H15: yes
A16: Id15 | B16: 36.385 | C16: 7.59 | D16: yes | E16: No | F16: No | G16: 2 | H16: yes
A17: Id16 | B17: 39.9 | C17: 11.32 | D17: No | E17: No | F17: No | G17: No major surgery | H17: yes
A18: Id17 | B18: 33.8 | C18: 7.67 | D18: No | E18: No | F18: No | G18: 3 | H18: yes
A19: Id18 | B19: 36.765 | C19: 7.29 | D19: yes | E19: No | F19: Yes | G19: 1 | H19: yes
A20: Id19 | B20: 36.955 | C20: 4.72 | D20: yes | E20: No | F20: No | G20: 1 | H20: yes
A21: Id20 | B21: 42.9 | C21: 11.41 | D21: No | E21: No | F21: No | G21: No major surgery | H21: yes
A22: Id21 | B22: 36.3 | C22: 11.5 | D22: yes | E22: No | F22: No | G22: 2 | H22: yes
A23: Id22 | B23: 32.2 | C23: 6.22 | D23: yes | E23: No | F23: No | G23: 2 | H23: yes
A24: Id23 | B24: 31.3 | C24: 11.38 | D24: No | E24: No | F24: No | G24: 3 | H24: yes
A25: Id24 | B25: 41.8 | C25: 7.89 | D25: yes | E25: No | F25: No | G25: 2 | H25: yes
A26: Id25 | B26: 35.09 | C26: 4.38 | D26: yes | E26: No | F26: No | G26: 2 | H26: yes
A27: Id26 | B27: 33.88 | C27: 7.01 | D27: No | E27: No | F27: No | G27: 3 | H27: yes
A28: Id27 | B28: 30.875 | C28: 11.88 | D28: No | E28: No | F28: No | G28: No major surgery | H28: yes
A29: Id28 | B29: 36.86 | C29: 5.19 | D29: yes | E29: No | F29: Yes | G29: 1 | H29: yes
A30: Id29 | B30: 35.86 | C30: 6.74 | D30: yes | E30: No | F30: No | G30: 2 | H30: yes
A31: Id30 | B31: 37.05 | C31: 8.44 | D31: No | E31: No | F31: No | G31: No major surgery | H31: yes
A32: Id31 | B32: 43.89 | C32: 8.71 | D32: No | E32: No | F32: No | G32: No major surgery | H32: yes
A33: Id32 | B33: 42.35 | C33: 5.08 | D33: yes | E33: No | F33: No | G33: No major surgery | H33: yes
A34: Id33 | B34: 31.35 | C34: 6.86 | D34: No | E34: No | F34: No | G34: No major surgery | H34: yes
A35: Id34 | B35: 47.6 | C35: 5.95 | D35: yes | E35: No | F35: No | G35: No major surgery | H35: yes
A36: Id35 | B36: 46.2 | C36: 6.09 | D36: No | E36: No | F36: Yes | G36: 1 | H36: yes
A37: Id36 | B37: 32.015 | C37: 11.75 | D37: No | E37: No | F37: No | G37: No major surgery | H37: yes
A38: Id37 | B38: 40.565 | C38: 7.37 | D38: No | E38: No | F38: No | G38: No major surgery | H38: yes
A39: Id38 | B39: 32.45 | C39: 11.91 | D39: No | E39: No | F39: No | G39: No major surgery | H39: yes
A40: Id39 | B40: 34.96 | C40: 6.52 | D40: No | E40: No | F40: No | G40: No major surgery | H40: yes
...

Sheet Errors in Hospitalisation Detai
A1: Row Number | B1: Customer ID | C1: Date of Birth | D1: children | E1: charges | F1: Hospital tier | G1: City tier | H1: State ID | I1: Age

Sheet Hospitalisation Details (3)
A1: Customer ID | B1: Date of Birth | C1: children | D1: charges | E1: Hospital tier | F1: City tier | G1: State ID
A2: Id1 | B2: 25123 | C2: 0 | D2: 63770.43 | E2: tier - 1 | F2: tier - 3 | G2: R1013
A3: Id10 | B3: 28853 | C3: 0 | D3: 48885.14 | E3: tier - 1 | F3: tier - 2 | G3: R1013
A4: Id100 | B4: 28303 | C4: 2 | D4: 40284.38 | E4: tier - 1 | F4: tier - 3 | G4: R1012
A5: Id1000 | B5: 32859 | C5: 3 | D5: 11250.43 | E5: tier - 3 | F5: tier - 2 | G5: R1026
A6: Id1001 | B6: 25567 | C6: 2 | D6: 11244.38 | E6: tier - 3 | F6: tier - 1 | G6: R1016
A7: Id1002 | B7: 27939 | C7: 2 | D7: 11217.35 | E7: tier - 3 | F7: tier - 2 | G7: R1025
A8: Id1003 | B8: 25733 | C8: 2 | D8: 11187.66 | E8: tier - 3 | F8: tier - 2 | G8: R1012
A9: Id1004 | B9: 26545 | C9: 0 | D9: 11186.2 | E9: tier - 3 | F9: tier - 2 | G9: R1021
A10: Id1005 | B10: 24325 | C10: 0 | D10: 11165.42 | E10: tier - 3 | F10: tier - 1 | G10: R1016
A11: Id1006 | B11: 25379 | C11: 2 | D11: 11163.57 | E11: tier - 3 | F11: tier - 2 | G11: R1011
A12: Id1007 | B12: 25537 | C12: 2 | D12: 11150.78 | E12: tier - 3 | F12: tier - 2 | G12: R1011
A13: Id1008 | B13: 29453 | C13: 2 | D13: 11103.33 | E13: tier - 3 | F13: tier - 1 | G13: R1021
... A1465: Id2317 | B1465: 35040 | C1465: 0 | D1465: 773.54 | E1465: tier - 3 | F1465: tier - 2 | G1465: R1013
A1466: Id2318 | C1466: 0 | D1466: 770.38 | E1466: tier - 3 | F1466: ? | G1466: R1012
A1467: Id2319 | B1467: 34148 | C1467: 0 | D1467: 770 | E1467: tier - 3 | F1467: tier - 3 | G1467: R1013
A1468: Id232 | B1468: 35060 | C1468: 1 | D1468: 34806.47 | E1468: tier - 1 | F1468: tier - 2 | G1468: R1013
A1469: Id2320 | B1469: 35360 | C1469: 0 | D1469: 760 | E1469: tier - 3 | F1469: tier - 3 | G1469: R1013
A1470: Id2321 | B1470: 34190 | C1470: 0 | D1470: 760 | E1470: tier - 3 | F1470: tier - 1 | G1470: R1013
A1471: Id2322 | C1471: 0 | D1471: 750 | E1471: tier - 3 | F1471: tier - 1 | G1471: R1012
A1472: Id2323 | B1472: 36508 | C1472: 0 | D1472: 722.99 | E1472: tier - 3 | F1472: tier - 1 | G1472: R1013
A1473: Id2324 | B1473: 36520 | C1473: 0 | D1473: 700 | E1473: ? | F1473: tier - 3 | G1473: R1013
A1474: Id2325 | B1474: 37146 | C1474: 0 | D1474: 687.54 | E1474: tier - 3 | F1474: tier - 2 | G1474: R1013
A1475: Id2326 | B1475: 35743 | C1475: 0 | D1475: 670 | E1475: tier - 3 | F1475: tier - 3 | G1475: R1013
A1476: Id2327 | B1476: 37589 | C1476: 0 | D1476: 668 | E1476: tier - 3 | F1476: tier - 2 | G1476: R1012
A1477: Id2328 | B1477: 34884 | C1477: 0 | D1477: 650 | E1477: tier - 3 | F1477: tier - 3 | G1477: R1013
A1478: Id2329 | B1478: 34121 | C1478: 0 | D1478: 650 | E1478: tier - 3 | F1478: tier - 3 | G1478: R1013
A1479: Id233 | B1479: 37805 | C1479: 0 | D1479: 34779.62 | E1479: tier - 1 | F1479: tier - 2 | G1479: R1011
A1480: Id2330 | B1480: 37215 | C1480: 0 | D1480: 646.14 | E1480: tier - 3 | F1480: tier - 3 | G1480: R1012
A1481: Id2331 | B1481: 36003 | C1481: 0 | D1481: 637.26 | E1481: tier - 3 | F1481: tier - 3 | G1481: R1013
A1482: Id2332 | B1482: 33860 | C1482: 0 | D1482: 604.54 | E1482: tier - 3 | F1482: tier - 3 | G1482: R1013
A1483: Id2333 | B1483: 34150 | C1483: 0 | D1483: 600 | E1483: tier - 2 | F1483: tier - 1 | G1483: R1013
... A1557: Id299 | B1557: 27696 | C1557: 1 | D1557: 31591.82 | E1557: tier - 2 | F1557: tier - 1 | G1557: R1011
A1558: Id3 | C1558: 3 | D1558: 60021.4 | E1558: tier - 1 | F1558: tier - 1 | G1558: R1012
A1559: Id30 | B1559: 26273 | C1559: 3 | D1559: 46255.11 | E1559: tier - 1 | F1559: tier - 3 | G1559: R1024
A1560: Id300 | B1560: 27310 | C1560: 0 | D1560: 31368.81 | E1560: tier - 2 | F1560: tier - 3 | G1560: R1011
A1561: Id301 | B1561: 34969 | C1561: 0 | D1561: 31328.27 | E1561: tier - 2 | F1561: tier - 2 | G1561: R1011
A1562: Id302 | B1562: 25028 | C1562: 0 | D1562: 31322.53 | E1562: tier - 2 | F1562: tier - 1 | G1562: R1011
A1563: Id303 | B1563: 36729 | C1563: 0 | D1563: 31234.56 | E1563: tier - 1 | F1563: tier - 1 | G1563: R1011
A1564: Id304 | B1564: 38300 | C1564: 0 | D1564: 31196.61 | E1564: tier - 2 | F1564: tier - 1 | G1564: R1011
...

Sheet Customer Names (3)
A1: Customer ID | B1: Title | C1: First Name | D1: Last Name
A2: Id1 | B2: Ms | C2: Hawks | D2: Kelly
A3: Id2 | B3: Mr | C3: Lehner | D3: Matthew D
A4: Id3 | B4: Mr | C4: Lu | D4: Phil
A5: Id4 | B5: Ms | C5: Osborne | D5: Kelsey
A6: Id5 | B6: Ms | C6: Kadala | D6: Kristyn
A7: Id6 | B7: Mr | C7: Baker | D7: Russell B.
A8: Id7 | B8: Mr | C8: Macpherson | D8: Scott
A9: Id8 | B9: Mr | C9: Hallman | D9: Stephen
A10: Id9 | B10: Mr | C10: Moran | D10: Patrick R.
A11: Id10 | B11: Ms | C11: Benner | D11: Brooke N.
A12: Id11 | B12: Ms | C12: Fierro Vargas | D12: Paola Andrea
... A2336: Id2335 | B2336: Mr | C2336: German | D2336: Aaron K

Sheet Medical Examinations (2)
A1: Customer ID | B1: BMI | C1: HBA1C | D1: Heart Issues | E1: Any Transplants | F1: Cancer history | G1: NumberOfMajorSurgeries | H1: smoker | I1: Weight Status | J1: Diabetes Status
A2: Id1 | B2: 47.41 | C2: 7.47 | D2: No | E2: No | F2: No | G2: 0 | H2: Yes | I2: Obesity | J2: Diabetes
A3: Id2 | B3: 30.36 | C3: 5.77 | D3: No | E3: No | F3: No | G3: 0 | H3: Yes | I3: Obesity | J3: Prediabetes
A4: Id3 | B4: 34.485 | C4: 11.87 | D4: Yes | E4: No | F4: No | G4: 2 | H4: Yes | I4: Obesity | J4: Diabetes
A5: Id4 | B5: 38.095 | C5: 6.05 | D5: No | E5: No | F5: No | G5: 0 | H5: Yes | I5: Obesity | J5: Prediabetes
A6: Id5 | B6: 35.53 | C6: 5.45 | D6: No | E6: No | F6: No | G6: 0 | H6: Yes | I6: Obesity | J6: Normal
A7: Id6 | B7: 32.8 | C7: 6.59 | D7: No | E7: No | F7: No | G7: 0 | H7: Yes | I7: Obesity | J7: Diabetes
A8: Id7 | B8: 36.4 | C8: 6.07 | D8: No | E8: No | F8: No | G8: 0 | H8: Yes | I8: Obesity | J8: Prediabetes
A9: Id8 | B9: 36.96 | C9: 7.93 | D9: No | E9: No | F9: No | G9: 3 | H9: Yes | I9: Obesity | J9: Diabetes
A10: Id9 | B10: 41.14 | C10: 9.58 | D10: Yes | E10: No | F10: Yes | G10: 1 | H10: Yes | I10: Obesity | J10: Diabetes
A11: Id10 | B11: 38.06 | C11: 10.79 | D11: No | E11: No | F11: No | G11: 0 | H11: Yes | I11: Obesity | J11: Diabetes
A12: Id11 | B12: 37.7 | C12: 5.96 | D12: Yes | E12: No | F12: No | G12: 2 | H12: Yes | I12: Obesity | J12: Prediabetes
A13: Id12 | B13: 42.13 | C13: 11.9 | D13: No | E13: No | F13: No | G13: 0 | H13: Yes | I13: Obesity | J13: Diabetes
... A2336: Id2335 | B2336: 17.58 | C2336: 4.51 | D2336: No | E2336: No | F2336: No | G2336: 1 | H2336: No | I2336: Underweight | J2336: Normal

Sheet Customer Names (2)
A1: Customer ID | B1: Title | C1: First Name | D1: Last Name
A2: Id1 | B2: Ms | C2: Hawks | D2: Kelly
A3: Id2 | B3: Mr | C3: Lehner | D3: Matthew D
A4: Id3 | B4: Mr | C4: Lu | D4: Phil
A5: Id4 | B5: Ms | C5: Osborne | D5: Kelsey
A6: Id5 | B6: Ms | C6: Kadala | D6: Kristyn
A7: Id6 | B7: Mr | C7: Baker | D7: Russell B.
A8: Id7 | B8: Mr | C8: Macpherson | D8: Scott
A9: Id8 | B9: Mr | C9: Hallman | D9: Stephen
A10: Id9 | B10: Mr | C10: Moran | D10: Patrick R.
A11: Id10 | B11: Ms | C11: Benner | D11: Brooke N.
A12: Id11 | B12: Ms | C12: Fierro Vargas | D12: Paola Andrea
... A2336: Id2335 | B2336: Mr | C2336: German | D2336: Aaron K

Sheet Healthcare
A1: Customer ID | B1: First Name | C1: BMI | D1: HBA1C | E1: Heart Issues | F1: Any Transplants | G1: Cancer history | H1: Number of Major Surgeries | I1: Smoker | J1: Weight Status | K1: Diabetes Status | L1: Date of Birth | M1: Charges | N1: Hospital tier | O1: City tier | P1: State ID | Q1: Age
A2: {='Customer Names (2)'!A2:A2336} -> Id1 | B2: =VLOOKUP(A2,'Customer Names (2)'!A:B, 2,FALSE) -> Ms | C2: =VLOOKUP(A2,Medical_Examinations[],2,FALSE) -> 47.41 | D2: =VLOOKUP(A2,Medical_Examinations[],3,FALSE) -> 7.47 | E2: =VLOOKUP(A2,Medical_Examinations[],4,FALSE) -> No | F2: =VLOOKUP(A2,Medical_Examinations[],5,FALSE) -> No | G2: =VLOOKUP(A2,Medical_Examinations[],6,FALSE) -> No | H2: =VLOOKUP(A2,Medical_Examinations[],7,FALSE) -> 0 | I2: =VLOOKUP(A2,Medical_Examinations[],8,FALSE) -> Yes | J2: =VLOOKUP(A2,Medical_Examinations[],9,FALSE) -> Obesity | K2: =VLOOKUP(A2,Medical_Examinations[],10,FALSE) -> Diabetes | M2: =VLOOKUP(A2,Hospitalisation_Details__2[],4,FALSE) -> 63770.43 | N2: =VLOOKUP(A2,Hospitalisation_Details__2[],5,FALSE) -> tier - 1 | O2: =VLOOKUP(A2,Hospitalisation_Details__2[],6,FALSE) -> tier - 3 | P2: =VLOOKUP(A2,Hospitalisation_Details__2[],7,FALSE) -> R1013
A3: Id2 | B3: =VLOOKUP(A3,'Customer Names (2)'!A:B, 2,FALSE) -> Mr | C3: =VLOOKUP(A3,Medical_Examinations[],2,FALSE) -> 30.36 | D3: =VLOOKUP(A3,Medical_Examinations[],3,FALSE) -> 5.77 | E3: =VLOOKUP(A3,Medical_Examinations[],4,FALSE) -> No | F3: =VLOOKUP(A3,Medical_Examinations[],5,FALSE) -> No | G3: =VLOOKUP(A3,Medical_Examinations[],6,FALSE) -> No | H3: =VLOOKUP(A3,Medical_Examinations[],7,FALSE) -> 0 | I3: =VLOOKUP(A3,Medical_Examinations[],8,FALSE) -> Yes | J3: =VLOOKUP(A3,Medical_Examinations[],9,FALSE) -> Obesity | K3: =VLOOKUP(A3,Medical_Examinations[],10,FALSE) -> Prediabetes | M3: =VLOOKUP(A3,Hospitalisation_Details__2[],4,FALSE) -> 62592.87 | N3: =VLOOKUP(A3,Hospitalisation_Details__2[],5,FALSE) -> tier - 2 | O3: =VLOOKUP(A3,Hospitalisation_Details__2[],6,FALSE) -> tier - 3 | P3: =VLOOKUP(A3,Hospitalisation_Details__2[],7,FALSE) -> R1013
A4: Id3 | B4: =VLOOKUP(A4,'Customer Names (2)'!A:B, 2,FALSE) -> Mr | C4: =VLOOKUP(A4,Medical_Examinations[],2,FALSE) -> 34.485 | D4: =VLOOKUP(A4,Medical_Examinations[],3,FALSE) -> 11.87 | E4: =VLOOKUP(A4,Medical_Examinations[],4,FALSE) -> Yes | F4: =VLOOKUP(A4,Medical_Examinations[],5,FALSE) -> No | G4: =VLOOKUP(A4,Medical_Examinations[],6,FALSE) -> No | H4: =VLOOKUP(A4,Medical_Examinations[],7,FALSE) -> 2 | I4: =VLOOKUP(A4,Medical_Examinations[],8,FALSE) -> Yes | J4: =VLOOKUP(A4,Medical_Examinations[],9,FALSE) -> Obesity | K4: =VLOOKUP(A4,Medical_Examinations[],10,FALSE) -> Diabetes | M4: =VLOOKUP(A4,Hospitalisation_Details__2[],4,FALSE) -> 60021.4 | N4: =VLOOKUP(A4,Hospitalisation_Details__2[],5,FALSE) -> tier - 1 | O4: =VLOOKUP(A4,Hospitalisation_Details__2[],6,FALSE) -> tier - 1 | P4: =VLOOKUP(A4,Hospitalisation_Details__2[],7,FALSE) -> R1012
A5: Id4 | B5: =VLOOKUP(A5,'Customer Names (2)'!A:B, 2,FALSE) -> Ms | C5: =VLOOKUP(A5,Medical_Examinations[],2,FALSE) -> 38.095 | D5: =VLOOKUP(A5,Medical_Examinations[],3,FALSE) -> 6.05 | E5: =VLOOKUP(A5,Medical_Examinations[],4,FALSE) -> No | F5: =VLOOKUP(A5,Medical_Examinations[],5,FALSE) -> No | G5: =VLOOKUP(A5,Medical_Examinations[],6,FALSE) -> No | H5: =VLOOKUP(A5,Medical_Examinations[],7,FALSE) -> 0 | I5: =VLOOKUP(A5,Medical_Examinations[],8,FALSE) -> Yes | J5: =VLOOKUP(A5,Medical_Examinations[],9,FALSE) -> Obesity | K5: =VLOOKUP(A5,Medical_Examinations[],10,FALSE) -> Prediabetes | M5: =VLOOKUP(A5,Hospitalisation_Details__2[],4,FALSE) -> 58571.07 | N5: =VLOOKUP(A5,Hospitalisation_Details__2[],5,FALSE) -> tier - 1 | O5: =VLOOKUP(A5,Hospitalisation_Details__2[],6,FALSE) -> tier - 3 | P5: =VLOOKUP(A5,Hospitalisation_Details__2[],7,FALSE) -> R1024
A6: Id5 | B6: =VLOOKUP(A6,'Customer Names (2)'!A:B, 2,FALSE) -> Ms | C6: =VLOOKUP(A6,Medical_Examinations[],2,FALSE) -> 35.53 | D6: =VLOOKUP(A6,Medical_Examinations[],3,FALSE) -> 5.45 | E6: =VLOOKUP(A6,Medical_Examinations[],4,FALSE) -> No | F6: =VLOOKUP(A6,Medical_Examinations[],5,FALSE) -> No | G6: =VLOOKUP(A6,Medical_Examinations[],6,FALSE) -> No | H6: =VLOOKUP(A6,Medical_Examinations[],7,FALSE) -> 0 | I6: =VLOOKUP(A6,Medical_Examinations[],8,FALSE) -> Yes | J6: =VLOOKUP(A6,Medical_Examinations[],9,FALSE) -> Obesity | K6: =VLOOKUP(A6,Medical_Examinations[],10,FALSE) -> Normal | M6: =VLOOKUP(A6,Hospitalisation_Details__2[],4,FALSE) -> 55135.4 | N6: =VLOOKUP(A6,Hospitalisation_Details__2[],5,FALSE) -> tier - 1 | O6: =VLOOKUP(A6,Hospitalisation_Details__2[],6,FALSE) -> tier - 2 | P6: =VLOOKUP(A6,Hospitalisation_Details__2[],7,FALSE) -> R1012
A7: Id6 | B7: =VLOOKUP(A7,'Customer Names (2)'!A:B, 2,FALSE) -> Mr | C7: =VLOOKUP(A7,Medical_Examinations[],2,FALSE) -> 32.8 | D7: =VLOOKUP(A7,Medical_Examinations[],3,FALSE) -> 6.59 | E7: =VLOOKUP(A7,Medical_Examinations[],4,FALSE) -> No | F7: =VLOOKUP(A7,Medical_Examinations[],5,FALSE) -> No | G7: =VLOOKUP(A7,Medical_Examinations[],6,FALSE) -> No | H7: =VLOOKUP(A7,Medical_Examinations[],7,FALSE) -> 0 | I7: =VLOOKUP(A7,Medical_Examinations[],8,FALSE) -> Yes | J7: =VLOOKUP(A7,Medical_Examinations[],9,FALSE) -> Obesity | K7: =VLOOKUP(A7,Medical_Examinations[],10,FALSE) -> Diabetes | M7: =VLOOKUP(A7,Hospitalisation_Details__2[],4,FALSE) -> 52590.83 | N7: =VLOOKUP(A7,Hospitalisation_Details__2[],5,FALSE) -> tier - 1 | O7: =VLOOKUP(A7,Hospitalisation_Details__2[],6,FALSE) -> tier - 3 | P7: =VLOOKUP(A7,Hospitalisation_Details__2[],7,FALSE) -> R1011
A8: Id7 | B8: =VLOOKUP(A8,'Customer Names (2)'!A:B, 2,FALSE) -> Mr | C8: =VLOOKUP(A8,Medical_Examinations[],2,FALSE) -> 36.4 | D8: =VLOOKUP(A8,Medical_Examinations[],3,FALSE) -> 6.07 | E8: =VLOOKUP(A8,Medical_Examinations[],4,FALSE) -> No | F8: =VLOOKUP(A8,Medical_Examinations[],5,FALSE) -> No | G8: =VLOOKUP(A8,Medical_Examinations[],6,FALSE) -> No | H8: =VLOOKUP(A8,Medical_Examinations[],7,FALSE) -> 0 | I8: =VLOOKUP(A8,Medical_Examinations[],8,FALSE) -> Yes | J8: =VLOOKUP(A8,Medical_Examinations[],9,FALSE) -> Obesity | K8: =VLOOKUP(A8,Medical_Examinations[],10,FALSE) -> Prediabetes | M8: =VLOOKUP(A8,Hospitalisation_Details__2[],4,FALSE) -> 51194.56 | N8: =VLOOKUP(A8,Hospitalisation_Details__2[],5,FALSE) -> tier - 1 | O8: =VLOOKUP(A8,Hospitalisation_Details__2[],6,FALSE) -> tier - 3 | P8: =VLOOKUP(A8,Hospitalisation_Details__2[],7,FALSE) -> R1011
A9: Id8 | B9: =VLOOKUP(A9,'Customer Names (2)'!A:B, 2,FALSE) -> Mr | C9: =VLOOKUP(A9,Medical_Examinations[],2,FALSE) -> 36.96 | D9: =VLOOKUP(A9,Medical_Examinations[],3,FALSE) -> 7.93 | E9: =VLOOKUP(A9,Medical_Examinations[],4,FALSE) -> No | F9: =VLOOKUP(A9,Medical_Examinations[],5,FALSE) -> No | G9: =VLOOKUP(A9,Medical_Examinations[],6,FALSE) -> No | H9: =VLOOKUP(A9,Medical_Examinations[],7,FALSE) -> 3 | I9: =VLOOKUP(A9,Medical_Examinations[],8,FALSE) -> Yes | J9: =VLOOKUP(A9,Medical_Examinations[],9,FALSE) -> Obesity | K9: =VLOOKUP(A9,Medical_Examinations[],10,FALSE) -> Diabetes | M9: =VLOOKUP(A9,Hospitalisation_Details__2[],4,FALSE) -> 49577.66 | N9: =VLOOKUP(A9,Hospitalisation_Details__2[],5,FALSE) -> tier - 2 | O9: =VLOOKUP(A9,Hospitalisation_Details__2[],6,FALSE) -> tier - 2 | P9: =VLOOKUP(A9,Hospitalisation_Details__2[],7,FALSE) -> R1013
A10: Id9 | B10: =VLOOKUP(A10,'Customer Names (2)'!A:B, 2,FALSE) -> Mr | C10: =VLOOKUP(A10,Medical_Examinations[],2,FALSE) -> 41.14 | D10: =VLOOKUP(A10,Medical_Examinations[],3,FALSE) -> 9.58 | E10: =VLOOKUP(A10,Medical_Examinations[],4,FALSE) -> Yes | F10: =VLOOKUP(A10,Medical_Examinations[],5,FALSE) -> No | G10: =VLOOKUP(A10,Medical_Examinations[],6,FALSE) -> Yes | H10: =VLOOKUP(A10,Medical_Examinations[],7,FALSE) -> 1 | I10: =VLOOKUP(A10,Medical_Examinations[],8,FALSE) -> Yes | J10: =VLOOKUP(A10,Medical_Examinations[],9,FALSE) -> Obesity | K10: =VLOOKUP(A10,Medical_Examinations[],10,FALSE) -> Diabetes | M10: =VLOOKUP(A10,Hospitalisation_Details__2[],4,FALSE) -> 48970.25 | N10: =VLOOKUP(A10,Hospitalisation_Details__2[],5,FALSE) -> tier - 1 | O10: =VLOOKUP(A10,Hospitalisation_Details__2[],6,FALSE) -> tier - 2 | P10: =VLOOKUP(A10,Hospitalisation_Details__2[],7,FALSE) -> R1013
A11: Id10 | B11: =VLOOKUP(A11,'Customer Names (2)'!A:B, 2,FALSE) -> Ms | C11: =VLOOKUP(A11,Medical_Examinations[],2,FALSE) -> 38.06 | D11: =VLOOKUP(A11,Medical_Examinations[],3,FALSE) -> 10.79 | E11: =VLOOKUP(A11,Medical_Examinations[],4,FALSE) -> No | F11: =VLOOKUP(A11,Medical_Examinations[],5,FALSE) -> No | G11: =VLOOKUP(A11,Medical_Examinations[],6,FALSE) -> No | H11: =VLOOKUP(A11,Medical_Examinations[],7,FALSE) -> 0 | I11: =VLOOKUP(A11,Medical_Examinations[],8,FALSE) -> Yes | J11: =VLOOKUP(A11,Medical_Examinations[],9,FALSE) -> Obesity | K11: =VLOOKUP(A11,Medical_Examinations[],10,FALSE) -> Diabetes | M11: =VLOOKUP(A11,Hospitalisation_Details__2[],4,FALSE) -> 48885.14 | N11: =VLOOKUP(A11,Hospitalisation_Details__2[],5,FALSE) -> tier - 1 | O11: =VLOOKUP(A11,Hospitalisation_Details__2[],6,FALSE) -> tier - 2 | P11: =VLOOKUP(A11,Hospitalisation_Details__2[],7,FALSE) -> R1013
A12: Id11 | B12: =VLOOKUP(A12,'Customer Names (2)'!A:B, 2,FALSE) -> Ms | C12: =VLOOKUP(A12,Medical_Examinations[],2,FALSE) -> 37.7 | D12: =VLOOKUP(A12,Medical_Examinations[],3,FALSE) -> 5.96 | E12: =VLOOKUP(A12,Medical_Examinations[],4,FALSE) -> Yes | F12: =VLOOKUP(A12,Medical_Examinations[],5,FALSE) -> No | G12: =VLOOKUP(A12,Medical_Examinations[],6,FALSE) -> No | H12: =VLOOKUP(A12,Medical_Examinations[],7,FALSE) -> 2 | I12: =VLOOKUP(A12,Medical_Examinations[],8,FALSE) -> Yes | J12: =VLOOKUP(A12,Medical_Examinations[],9,FALSE) -> Obesity | K12: =VLOOKUP(A12,Medical_Examinations[],10,FALSE) -> Prediabetes | M12: =VLOOKUP(A12,Hospitalisation_Details__2[],4,FALSE) -> 48824.45 | N12: =VLOOKUP(A12,Hospitalisation_Details__2[],5,FALSE) -> tier - 2 | O12: =VLOOKUP(A12,Hospitalisation_Details__2[],6,FALSE) -> tier - 1 | P12: =VLOOKUP(A12,Hospitalisation_Details__2[],7,FALSE) -> R1011
A13: Id12 | B13: =VLOOKUP(A13,'Customer Names (2)'!A:B, 2,FALSE) -> Mr | C13: =VLOOKUP(A13,Medical_Examinations[],2,FALSE) -> 42.13 | D13: =VLOOKUP(A13,Medical_Examinations[],3,FALSE) -> 11.9 | E13: =VLOOKUP(A13,Medical_Examinations[],4,FALSE) -> No | F13: =VLOOKUP(A13,Medical_Examinations[],5,FALSE) -> No | G13: =VLOOKUP(A13,Medical_Examinations[],6,FALSE) -> No | H13: =VLOOKUP(A13,Medical_Examinations[],7,FALSE) -> 0 | I13: =VLOOKUP(A13,Medical_Examinations[],8,FALSE) -> Yes | J13: =VLOOKUP(A13,Medical_Examinations[],9,FALSE) -> Obesity | K13: =VLOOKUP(A13,Medical_Examinations[],10,FALSE) -> Diabetes | M13: =VLOOKUP(A13,Hospitalisation_Details__2[],4,FALSE) -> 48675.52 | N13: =VLOOKUP(A13,Hospitalisation_Details__2[],5,FALSE) -> tier - 1 | O13: =VLOOKUP(A13,Hospitalisation_Details__2[],6,FALSE) -> tier - 2 | P13: =VLOOKUP(A13,Hospitalisation_Details__2[],7,FALSE) -> R1013
A14: Id13 | B14: =VLOOKUP(A14,'Customer Names (2)'!A:B, 2,FALSE) -> Mr | C14: =VLOOKUP(A14,Medical_Examinations[],2,FALSE) -> 40.92 | D14: =VLOOKUP(A14,Medical_Examinations[],3,FALSE) -> 8.41 | E14: =VLOOKUP(A14,Medical_Examinations[],4,FALSE) -> No | F14: =VLOOKUP(A14,Medical_Examinations[],5,FALSE) -> No | G14: =VLOOKUP(A14,Medical_Examinations[],6,FALSE) -> No | H14: =VLOOKUP(A14,Medical_Examinations[],7,FALSE) -> 0 | I14: =VLOOKUP(A14,Medical_Examinations[],8,FALSE) -> Yes | J14: =VLOOKUP(A14,Medical_Examinations[],9,FALSE) -> Obesity | K14: =VLOOKUP(A14,Medical_Examinations[],10,FALSE) -> Diabetes | M14: =VLOOKUP(A14,Hospitalisation_Details__2[],4,FALSE) -> 48673.56 | N14: =VLOOKUP(A14,Hospitalisation_Details__2[],5,FALSE) -> tier - 1 | O14: =VLOOKUP(A14,Hospitalisation_Details__2[],6,FALSE) -> tier - 2 | P14: =VLOOKUP(A14,Hospitalisation_Details__2[],7,FALSE) -> R1013
... A2336: Id2335 | B2336: =VLOOKUP(A2336,'Customer Names (2)'!A:B, 2,FALSE) -> Mr | C2336: =VLOOKUP(A2336,Medical_Examinations[],2,FALSE) -> 17.58 | D2336: =VLOOKUP(A2336,Medical_Examinations[],3,FALSE) -> 4.51 | E2336: =VLOOKUP(A2336,Medical_Examinations[],4,FALSE) -> No | F2336: =VLOOKUP(A2336,Medical_Examinations[],5,FALSE) -> No | G2336: =VLOOKUP(A2336,Medical_Examinations[],6,FALSE) -> No | H2336: =VLOOKUP(A2336,Medical_Examinations[],7,FALSE) -> 1 | I2336: =VLOOKUP(A2336,Medical_Examinations[],8,FALSE) -> No | J2336: =VLOOKUP(A2336,Medical_Examinations[],9,FALSE) -> Underweight | K2336: =VLOOKUP(A2336,Medical_Examinations[],10,FALSE) -> Normal | M2336: =VLOOKUP(A2336,Hospitalisation_Details__2[],4,FALSE) -> 563.84 | N2336: =VLOOKUP(A2336,Hospitalisation_Details__2[],5,FALSE) -> tier - 2 | O2336: =VLOOKUP(A2336,Hospitalisation_Details__2[],6,FALSE) -> tier - 3 | P2336: =VLOOKUP(A2336,Hospitalisation_Details__2[],7,FALSE) -> R1013
